<?xml version="1.0"?>
<robot xmlns:xacro="http://www.ros.org/wiki/xacro" name="wheel">
    <xacro:macro name="wheel" params="name parent joint_origin_xyz">
        <link name="${name}_link">
            <inertial>
                <origin rpy="0 1.5707 1.5707" xyz="0 0 0"/>
                <mass value="0.1"/>
                <inertia ixx="0.001" ixy="0.0" ixz="0.0" iyy="0.001" iyz="0.0" izz="0.001"/>
            </inertial>
            <visual>
                <origin rpy="0 1.5707 1.5707" xyz="0 0 0"/>
                <geometry>
                    <cylinder length="0.026" radius="0.0325"/>
                </geometry>
            </visual>
            <collision>
                <origin rpy="0 1.5707 1.5707" xyz="0 0 0"/>
                <geometry>
                    <cylinder length="0.026" radius="0.0325"/>
                </geometry>
            </collision>
        </link>

        <gazebo reference="${name}_link">
            <kp>1000000000000000000000000000.0</kp>
            <kd>1000000000000000000000000000.0</kd>
            <mu1>10.0</mu1>
            <mu2>10.0</mu2>
            <material>Gazebo/Yellow</material>
        </gazebo>

        <joint name="${name}_joint" type="continuous">
            <origin rpy="0 0 0" xyz="${joint_origin_xyz}"/>
            <parent link="${parent}"/>
            <child link="${name}_link"/>
            <axis rpy="0 0 0" xyz="0 1 0"/>
            <limit effort="10000" velocity="1000"/>
            <joint_properties damping="1.0" friction="1.0"/>
        </joint>
    </xacro:macro>
</robot>
